Workbook

Sheet Portfolio Guide
A1: ENERGY SAVINGS MODEL | PORTFOLIO DEMO
A2: An anonymized Excel case study demonstrating linked assumptions, projections, actuals, cost savings, and CO2 impact.
A4: STORY IN BRIEF
A5: This fictional municipal LED retrofit reduces first-year electricity consumption from a 1,080,000 kWh baseline to 367,300 kWh — a 66.0% reduction. The linked model translates project assumptions into monthly projections, invoice actuals, operating-cost performance, energy-price scenarios, and an estimated 377.73 tonnes of avoided CO2 in Year 1. Yellow cells are illustrative inputs; calculated outputs remain live formulas. All names, identifiers, dates, and figures are invented for portfolio use.
A9: SHEET | B9: PURPOSE
A10: General Data | B10: Project assumptions, guarantee terms, system capacity, and key savings outputs
A11: Projection | B11: Monthly and quarterly projected electricity consumption and cost
A12: Year 1 | B12: Illustrative monthly actuals with quarterly and trend comparisons
A13: Operating Costs | B13: Fifteen-year operating-cost and guaranteed-savings performance
A14: CO2 Impact | B14: Electricity savings and avoided CO2 emissions by year
A15: Cost Comparison | B15: Before/after reconstruction cost composition for Year 1
A16: Energy Price | B16: Fifteen-year price escalation and electricity cost scenario
A17: Average Price | B17: Monthly electricity tariff component model
A18: System Consumption | B18: Fifteen-year system consumption trend

Sheet General Data
A1: PORTFOLIO DEMO | B1: ENERGY SAVINGS REPORT | K1: DEMO-ESCO-01
A2: Contract Name | B2: Municipal LED Street Lighting Modernization – Portfolio Demo
A3: Contract Number | B3: DEMO-ESCO-2026-01
A4: Contract Date | B4: 46037
A6: Updated by: | B6: Portfolio Analyst
A7: Last updated: | B7: =TODAY() -> 46245
A9: Proposal Number | B9: DEMO-BID-026
A10: Report Date | B10: 46245
A12: Preparation Phase: | B12: 1
A13: Implementation Phase: | B13: 1
A14: Guarantee Phase: | B14: =MIN(1,MAX(0,YEARFRAC(B16,B10)/B17)) -> 0.024074074
A16: Guarantee Start Date: | B16: 46113
A17: Guarantee Period (years): | B17: 15
A18: Guarantee End Date: | B18: =EDATE(B16,B17*12) -> 51592
A20: Contract Value: NET | B20: 1850000
A21: Fixtures per Tender: | B21: 1200
A22: Installed Fixtures: | B22: 1175 | C22: =+B22+B23 -> 1200
A23: Additional Installed Fixtures: | B23: 25
A24: Remaining Fixtures: | B24: =+B21-(B22+B23) -> 0
A25: Intervention Fixtures: | B25: 12
A26: Control Systems: | B26: 48
A27: Tender – Bid Form
A28: Reference System Consumption [kWh] | B28: 1080000
A29: Reference Installed Capacity [kW] | B29: 190 | G29: January | H29: 435.63333 | I29: 0.10894283
A30: Reference Energy Cost | B30: 8600000 | C30: =+B30/$B$37 -> 73504.274 | G30: February | H30: 361.13333 | I30: 0.090311932
A31: Reference Maintenance Cost | B31: 2600000 | C31: =+B31/$B$37 -> 22222.222 | G31: March | H31: 352.51667 | I31: 0.088157083
A32: Reference Operating Cost | B32: =SUM(B30:B31) -> 11200000 | C32: =+B32/B37 -> 95726.496 | G32: April | H32: 291.81667 | I32: 0.072977276
A33: Reference Electricity Price [RSD/kWh] | B33: 8.2 | G33: May | H33: 255.8 | I33: 0.063970257
A34: Reference Electricity Price [EUR/kWh] | B34: =B33/B37 -> 0.07008547 | G34: June | H34: 223.11667 | I34: 0.055796836
A35: Guaranteed Annual Operating Cost Savings | B35: 68000 | G35: July | H35: 241.25 | I35: 0.060331605
G36: August | H36: 281.03333 | I36: 0.070280589
A37: Exchange Rate at Publication | B37: 117 | G37: September | H37: 319.61667 | I37: 0.079929478
G38: October | H38: 379.43333 | I38: 0.094888381
A39: Installed Capacity [kW] | B39: 190 | G39: November | H39: 410.56667 | I39: 0.10267418
A40: Guaranteed Consumption [kWh] | B40: 380000 | G40: December | H40: 446.81667 | I40: 0.11173955
A41: Projected Consumption [kWh] | B41: =Projection!B17 -> 399873 | H41: =+SUM(H29:H40) -> 3998.7333 | I41: =+SUM(I29:I40) -> 1
A42: Projected Annual Electricity Cost | B42: =B41*B34 -> 28025.287
A43: Projected Annual Maintenance Cost | B43: 0
A44: Annual Electricity Savings [kWh] | B44: =+B28-B40 -> 700000
A45: Annual Electricity Cost Savings | B45: =C30-B42 -> 45478.986
...

Sheet Projection
A1: PORTFOLIO DEMO | C1: ENERGY SAVINGS REPORT | K1: DEMO-ESCO-01
A2: DATE AND RECORD
A4: Month | B4: Electricity Consumed [kWh] | C4: Cost excl. VAT [RSD] | D4: Cost excl. VAT [EUR] | F4: Electricity +5% [kWh] | J4: Month | K4: Electricity Consumed [kWh] | P4: Quarter | Q4: Electricity +5% [kWh]
A5: January | B5: =+'General Data'!$C$61*'General Data'!I29 -> 43563.297 | C5: =B5*'General Data'!$B$33 -> 357219.04 | D5: =B5*'General Data'!$B$34 -> 3053.1542 | F5: =+B5*1.05 -> 45741.462 | J5: January | P5: Q1 | Q5: =+F5+F6+F7 -> 120674.65
A6: February | B6: =+'General Data'!$C$61*'General Data'!I30 -> 36113.303 | C6: =B6*'General Data'!$B$33 -> 296129.09 | D6: =B6*'General Data'!$B$34 -> 2531.0178 | F6: =+B6*1.05 -> 37918.968 | J6: February
A7: March | B7: =+'General Data'!$C$61*'General Data'!I31 -> 35251.637 | C7: =B7*'General Data'!$B$33 -> 289063.43 | D7: =B7*'General Data'!$B$34 -> 2470.6276 | F7: =+B7*1.05 -> 37014.219 | J7: March
A8: April | B8: =+'General Data'!$C$61*'General Data'!I32 -> 29181.642 | C8: =B8*'General Data'!$B$33 -> 239289.47 | D8: =B8*'General Data'!$B$34 -> 2045.2091 | F8: =+B8*1.05 -> 30640.724 | J8: Total | K8: =+SUM(K5:K7) -> 0 | P8: Q2 | Q8: =+F8+F9+F10 -> 80926.933
A9: May | B9: =+'General Data'!$C$61*'General Data'!I33 -> 25579.979 | C9: =B9*'General Data'!$B$33 -> 209755.83 | D9: =B9*'General Data'!$B$34 -> 1792.7848 | F9: =+B9*1.05 -> 26858.978
A10: June | B10: =+'General Data'!$C$61*'General Data'!I34 -> 22311.648 | C10: =B10*'General Data'!$B$33 -> 182955.51 | D10: =B10*'General Data'!$B$34 -> 1563.7223 | F10: =+B10*1.05 -> 23427.23
A11: July | B11: =+'General Data'!$C$61*'General Data'!I35 -> 24124.98 | C11: =B11*'General Data'!$B$33 -> 197824.84 | D11: =B11*'General Data'!$B$34 -> 1690.8106 | F11: =+B11*1.05 -> 25331.229 | P11: Q3 | Q11: =+F11+F12+F13 -> 88399.426
A12: August | B12: =+'General Data'!$C$61*'General Data'!I36 -> 28103.31 | C12: =B12*'General Data'!$B$33 -> 230447.14 | D12: =B12*'General Data'!$B$34 -> 1969.6337 | F12: =+B12*1.05 -> 29508.475
A13: September | B13: =+'General Data'!$C$61*'General Data'!I37 -> 31961.64 | C13: =B13*'General Data'!$B$33 -> 262085.45 | D13: =B13*'General Data'!$B$34 -> 2240.0466 | F13: =+B13*1.05 -> 33559.722
A14: October | B14: =+'General Data'!$C$61*'General Data'!I38 -> 37943.302 | C14: =B14*'General Data'!$B$33 -> 311135.07 | D14: =B14*'General Data'!$B$34 -> 2659.2741 | F14: =+B14*1.05 -> 39840.467 | P14: Q4 | Q14: =+F14+F15+F16 -> 129865.64
A15: November | B15: =+'General Data'!$C$61*'General Data'!I39 -> 41056.632 | C15: =B15*'General Data'!$B$33 -> 336664.39 | D15: =B15*'General Data'!$B$34 -> 2877.4734 | F15: =+B15*1.05 -> 43109.464
A16: December | B16: =+'General Data'!$C$61*'General Data'!I40 -> 44681.629 | C16: =B16*'General Data'!$B$33 -> 366389.36 | D16: =B16*'General Data'!$B$34 -> 3131.533 | F16: =+B16*1.05 -> 46915.711
B17: =SUM(B5:B16) -> 399873 | C17: =SUM(C5:C16) -> 3278958.6 | D17: =SUM(D5:D16) -> 28025.287 | F17: =SUM(F5:F16) -> 419866.65 | Q17: =+Q14+Q11+Q8+Q5 -> 419866.65
A19: Projection – Original Engineering Model
A21: Month | B21: Electricity Consumed [kWh]
A22: January | B22: =+B5 -> 43563.297
A23: February | B23: =+B6 -> 36113.303
A24: March | B24: =+B7 -> 35251.637
A25: April | B25: =+B8 -> 29181.642
A26: May | B26: =+B9 -> 25579.979
A27: June | B27: =+B10 -> 22311.648
A28: July | B28: =+B11 -> 24124.98
A29: August | B29: =+B12 -> 28103.31
A30: September | B30: =+B13 -> 31961.64
A31: October | B31: =+B14 -> 37943.302
A32: November | B32: =+B15 -> 41056.632
A33: December | B33: =+B16 -> 44681.629
B34: =SUM(B22:B33) -> 399873

Sheet Year 1
A1: PORTFOLIO DEMO | C1: ENERGY SAVINGS REPORT | I1: DEMO-ESCO-01
C2: Actual | H2: Projection
A3: Year | B3: Month | C3: Electricity Consumed [kWh] | D3: Cost excl. VAT [RSD] | E3: Cost excl. VAT [EUR] | F3: Invoice Consumption excl. Added Loads [kWh] | G3: Cost at Reference Energy Price [EUR] | H3: Projected Consumption [kWh]
A4: 2026 | B4: September | C4: 34200 | D4: =C4*'General Data'!$B$33 -> 280440 | E4: =+D4/'General Data'!$B$37 -> 2396.9231 | F4: =+C4-'General Data'!$B$60*4000*'General Data'!I37 -> 32675.505 | G4: =+F4*'General Data'!$B$34 -> 2290.0781 | H4: =+Projection!B13 -> 31961.64 | K4: =+C4-H4 -> 2238.36 | M4: =+C4*'General Data'!$B$34 -> 2396.9231
A5: 2026 | B5: October | C5: 35500 | D5: =C5*'General Data'!$B$33 -> 291100 | E5: =+D5/'General Data'!$B$37 -> 2488.0342 | F5: =+C5-'General Data'!$B$60*4000*'General Data'!I38 -> 33690.194 | G5: =+F5*'General Data'!$B$34 -> 2361.1931 | H5: =+Projection!B14 -> 37943.302 | K5: =+C5-H5 -> -2443.3017 | M5: =+C5*'General Data'!$B$34 -> 2488.0342
A6: 2026 | B6: November | C6: 37100 | D6: =C6*'General Data'!$B$33 -> 304220 | E6: =+D6/'General Data'!$B$37 -> 2600.1709 | F6: =+C6-'General Data'!$B$60*4000*'General Data'!I39 -> 35141.695 | G6: =+F6*'General Data'!$B$34 -> 2462.9222 | H6: =+Projection!B15 -> 41056.632 | K6: =+C6-H6 -> -3956.6324 | M6: =+C6*'General Data'!$B$34 -> 2600.1709
A7: 2026 | B7: December | C7: 38000 | D7: =C7*'General Data'!$B$33 -> 311600 | E7: =+D7/'General Data'!$B$37 -> 2663.2479 | F7: =+C7-'General Data'!$B$60*4000*'General Data'!I40 -> 35868.792 | G7: =+F7*'General Data'!$B$34 -> 2513.8811 | H7: =+Projection!B16 -> 44681.629 | K7: =+C7-H7 -> -6681.6294 | M7: =+C7*'General Data'!$B$34 -> 2663.2479
A8: 2027 | B8: January | C8: 38100 | D8: =C8*'General Data'!$B$33 -> 312420 | E8: =+D8/'General Data'!$B$37 -> 2670.2564 | F8: =+C8-'General Data'!$B$60*4000*'General Data'!I29 -> 36022.133 | G8: =+F8*'General Data'!$B$34 -> 2524.6282 | H8: =+Projection!B5 -> 43563.297 | K8: =+C8-H8 -> -5463.297 | M8: =+C8*'General Data'!$B$34 -> 2670.2564
A9: 2027 | B9: February | C9: 29800 | D9: =C9*'General Data'!$B$33 -> 244360 | E9: =+D9/'General Data'!$B$37 -> 2088.547 | F9: =+C9-'General Data'!$B$60*4000*'General Data'!I30 -> 28077.481 | G9: =+F9*'General Data'!$B$34 -> 1967.8234 | H9: =+Projection!B6 -> 36113.303 | K9: =+C9-H9 -> -6313.3032 | M9: =+C9*'General Data'!$B$34 -> 2088.547
A10: 2027 | B10: March | C10: 28750 | D10: =C10*'General Data'!$B$33 -> 235750 | E10: =+D10/'General Data'!$B$37 -> 2014.9573 | F10: =+C10-'General Data'!$B$60*4000*'General Data'!I31 -> 27068.58 | G10: =+F10*'General Data'!$B$34 -> 1897.1142 | H10: =+Projection!B7 -> 35251.637 | K10: =+C10-H10 -> -6501.6373 | M10: =+C10*'General Data'!$B$34 -> 2014.9573
A11: 2027 | B11: April | C11: 28500 | D11: =C11*'General Data'!$B$33 -> 233700 | E11: =+D11/'General Data'!$B$37 -> 1997.4359 | F11: =+C11-'General Data'!$B$60*4000*'General Data'!I32 -> 27108.104 | G11: =+F11*'General Data'!$B$34 -> 1899.8842 | H11: =+Projection!B8 -> 29181.642 | K11: =+C11-H11 -> -681.64234 | M11: =+C11*'General Data'!$B$34 -> 1997.4359
A12: 2027 | B12: May | C12: 24100 | D12: =C12*'General Data'!$B$33 -> 197620 | E12: =+D12/'General Data'!$B$37 -> 1689.0598 | F12: =+C12-'General Data'!$B$60*4000*'General Data'!I33 -> 22879.895 | G12: =+F12*'General Data'!$B$34 -> 1603.5482 | H12: =+Projection!B9 -> 25579.979 | K12: =+C12-H12 -> -1479.9787 | M12: =+C12*'General Data'!$B$34 -> 1689.0598
A13: 2027 | B13: June | C13: 23500 | D13: =C13*'General Data'!$B$33 -> 192700 | E13: =+D13/'General Data'!$B$37 -> 1647.0085 | F13: =+C13-'General Data'!$B$60*4000*'General Data'!I34 -> 22435.787 | G13: =+F13*'General Data'!$B$34 -> 1572.4227 | H13: =+Projection!B10 -> 22311.648 | K13: =+C13-H13 -> 1188.3519 | M13: =+C13*'General Data'!$B$34 -> 1647.0085
A14: 2027 | B14: July | C14: 24450 | D14: =C14*'General Data'!$B$33 -> 200490 | E14: =+D14/'General Data'!$B$37 -> 1713.5897 | F14: =+C14-'General Data'!$B$60*4000*'General Data'!I35 -> 23299.295 | G14: =+F14*'General Data'!$B$34 -> 1632.9421 | H14: =+Projection!B11 -> 24124.98 | K14: =+C14-H14 -> 325.02011 | M14: =+C14*'General Data'!$B$34 -> 1713.5897
A15: 2027 | B15: August | C15: 25300 | D15: =C15*'General Data'!$B$33 -> 207460 | E15: =+D15/'General Data'!$B$37 -> 1773.1624 | F15: =+C15-'General Data'!$B$60*4000*'General Data'!I36 -> 23959.538 | G15: =+F15*'General Data'!$B$34 -> 1679.2155 | H15: =+Projection!B12 -> 28103.31 | K15: =+C15-H15 -> -2803.3099 | M15: =+C15*'General Data'!$B$34 -> 1773.1624
B16: Σ | C16: =SUM(C4:C15) -> 367300 | D16: =SUM(D4:D15) -> 3011860 | E16: =SUM(E4:E15) -> 25742.393 | F16: =SUM(F4:F15) -> 348227 | G16: =SUM(G4:G15) -> 24405.653 | H16: =SUM(H4:H15) -> 399873 | K16: =+C16-H16 -> -32573 | M16: =SUM(M4:M15) -> 25742.393
K18: =+K16/H16 -> -0.081458363
A20: Month | B20: Invoice Consumption [kWh]
A21: September | B21: 30200
A22: October | B22: 31850
A23: November | B23: 34200
A24: Total | B24: =SUM(B21:B23) -> 96250
B27: Month 1 | C27: Month 2 | D27: Month 3 | E27: Reporting Period Total
A28: Actual | B28: =+C4 -> 34200 | C28: =+C5 -> 35500 | D28: =+C6 -> 37100 | E28: =SUM(B28:D28) -> 106800
A29: Projection | B29: =+H4 -> 31961.64 | C29: =+H5 -> 37943.302 | D29: =+H6 -> 41056.632 | E29: =SUM(B29:D29) -> 110961.57
A30: Variance | B30: =+B28-B29 -> 2238.36 | C30: =+C28-C29 -> -2443.3017 | D30: =+D28-D29 -> -3956.6324 | E30: =SUM(B30:D30) -> -4161.5742
B31: =+B30/B29 -> 0.070032701 | C31: =+C30/C29 -> -0.064393492 | D31: =+D30/D29 -> -0.096370116 | E31: =+E30/E29 -> -0.037504642
B34: Month 1 | C34: Month 2 | D34: Month 3 | E34: Reporting Period Total
A35: Actual | B35: =+C7 -> 38000 | C35: =+C8 -> 38100 | D35: =+C9 -> 29800 | E35: =SUM(B35:D35) -> 105900
A36: Projection | B36: =+H7 -> 44681.629 | C36: =+H8 -> 43563.297 | D36: =+H9 -> 36113.303 | E36: =SUM(B36:D36) -> 124358.23
A37: Variance | B37: =+B35-B36 -> -6681.6294 | C37: =+C35-C36 -> -5463.297 | D37: =+D35-D36 -> -6313.3032 | E37: =SUM(B37:D37) -> -18458.23
B38: =+B37/B36 -> -0.14953862 | C38: =+C37/C36 -> -0.12541055 | D38: =+D37/D36 -> -0.17481932 | E38: =+E37/E36 -> -0.14842789
B41: Month 1 | C41: Month 2 | D41: Month 3 | E41: Reporting Period Total
A42: Actual | B42: =+C10 -> 28750 | C42: =+C11 -> 28500 | D42: =+C12 -> 24100 | E42: =SUM(B42:D42) -> 81350
A43: Projection | B43: =+H10 -> 35251.637 | C43: =+H11 -> 29181.642 | D43: =+H12 -> 25579.979 | E43: =SUM(B43:D43) -> 90013.258
A44: Variance | B44: =+B42-B43 -> -6501.6373 | C44: =+C42-C43 -> -681.64234 | D44: =+D42-D43 -> -1479.9787 | E44: =SUM(B44:D44) -> -8663.2583
B45: =+B44/B43 -> -0.18443504 | C45: =+C44/C43 -> -0.023358601 | D45: =+D44/D43 -> -0.057856916 | E45: =+E44/E43 -> -0.096244247
B48: Month 1 | C48: Month 2 | D48: Month 3 | E48: Reporting Period Total
A49: Actual | B49: =+C13 -> 23500 | C49: =+C14 -> 24450 | D49: =+C15 -> 25300 | E49: =SUM(B49:D49) -> 73250
A50: Projection | B50: =+H13 -> 22311.648 | C50: =+H14 -> 24124.98 | D50: =+H15 -> 28103.31 | E50: =SUM(B50:D50) -> 74539.938
...

Sheet Operating Costs
A1: PORTFOLIO DEMO | C1: ENERGY SAVINGS REPORT | I1: DEMO-ESCO-01
A2: Guarantee Year | B2: Maintenance Cost | C2: Electricity Cost at Reference Price | D2: Operating Cost | F2: Operating Cost Savings Achieved | G2: Variance vs Guaranteed Savings | H2: Variance [%]
A3: 1 | B3: 0 | C3: =+'Year 1'!G16 -> 24405.653 | D3: =+C3+B3 -> 24405.653 | F3: =+'General Data'!$C$32-'Operating Costs'!D3 -> 71320.843 | G3: =+F3-'General Data'!$B$35 -> 3320.8427 | H3: =+G3/'General Data'!$B$35 -> 0.048835923 | J3: =IF(ABS(H3)<0.0501,"OK","FALSE") -> OK | K3: =IF(ABS(H3)<0.0501,"✔","✖") -> ✔
A4: 2 | B4: =B3*1.02 -> 0 | C4: ='Energy Price'!F8 -> 27576.258 | D4: =+C4+B4 -> 27576.258 | F4: =+'General Data'!$C$32-'Operating Costs'!D4 -> 68150.237 | G4: =+F4-'General Data'!$B$35 -> 150.23732 | H4: =+G4/'General Data'!$B$35 -> 0.0022093724 | J4: =IF(ABS(H4)<0.0501,"OK","FALSE") -> OK | K4: =IF(ABS(H4)<0.0501,"✔","✖") -> ✔
A5: 3 | B5: =B4*1.02 -> 0 | C5: ='Energy Price'!F9 -> 28180.868 | D5: =+C5+B5 -> 28180.868 | F5: =+'General Data'!$C$32-'Operating Costs'!D5 -> 67545.628 | G5: =+F5-'General Data'!$B$35 -> -454.37214 | H5: =+G5/'General Data'!$B$35 -> -0.0066819433 | J5: =IF(ABS(H5)<0.0501,"OK","FALSE") -> OK | K5: =IF(ABS(H5)<0.0501,"✔","✖") -> ✔
A6: 4 | B6: =B5*1.02 -> 0 | C6: ='Energy Price'!F10 -> 28798.733 | D6: =+C6+B6 -> 28798.733 | F6: =+'General Data'!$C$32-'Operating Costs'!D6 -> 66927.762 | G6: =+F6-'General Data'!$B$35 -> -1072.2377 | H6: =+G6/'General Data'!$B$35 -> -0.015768201 | J6: =IF(ABS(H6)<0.0501,"OK","FALSE") -> OK | K6: =IF(ABS(H6)<0.0501,"✔","✖") -> ✔
A7: 5 | B7: =B6*1.02 -> 0 | C7: ='Energy Price'!F11 -> 29430.146 | D7: =+C7+B7 -> 29430.146 | F7: =+'General Data'!$C$32-'Operating Costs'!D7 -> 66296.35 | G7: =+F7-'General Data'!$B$35 -> -1703.6499 | H7: =+G7/'General Data'!$B$35 -> -0.025053675 | J7: =IF(ABS(H7)<0.0501,"OK","FALSE") -> OK | K7: =IF(ABS(H7)<0.0501,"✔","✖") -> ✔
A8: 6 | B8: =B7*1.02 -> 0 | C8: ='Energy Price'!F12 -> 30075.402 | D8: =+C8+B8 -> 30075.402 | F8: =+'General Data'!$C$32-'Operating Costs'!D8 -> 65651.094 | G8: =+F8-'General Data'!$B$35 -> -2348.9058 | H8: =+G8/'General Data'!$B$35 -> -0.034542733 | J8: =IF(ABS(H8)<0.0501,"OK","FALSE") -> OK | K8: =IF(ABS(H8)<0.0501,"✔","✖") -> ✔
A9: 7 | B9: =B8*1.02 -> 0 | C9: ='Energy Price'!F13 -> 30734.805 | D9: =+C9+B9 -> 30734.805 | F9: =+'General Data'!$C$32-'Operating Costs'!D9 -> 64991.691 | G9: =+F9-'General Data'!$B$35 -> -3008.309 | H9: =+G9/'General Data'!$B$35 -> -0.044239839 | J9: =IF(ABS(H9)<0.0501,"OK","FALSE") -> OK | K9: =IF(ABS(H9)<0.0501,"✔","✖") -> ✔
A10: 8 | B10: =B9*1.02 -> 0 | C10: 28345 | D10: =+C10+B10 -> 28345 | F10: =+'General Data'!$C$32-'Operating Costs'!D10 -> 67381.496 | G10: =+F10-'General Data'!$B$35 -> -618.50427 | H10: =+G10/'General Data'!$B$35 -> -0.0090956511 | J10: =IF(ABS(H10)<0.0501,"OK","FALSE") -> OK | K10: =IF(ABS(H10)<0.0501,"✔","✖") -> ✔
A11: 9 | B11: =B10*1.02 -> 0 | C11: 25234 | D11: =+C11+B11 -> 25234 | F11: =+'General Data'!$C$32-'Operating Costs'!D11 -> 70492.496 | G11: =+F11-'General Data'!$B$35 -> 2492.4957 | H11: =+G11/'General Data'!$B$35 -> 0.036654349 | J11: =IF(ABS(H11)<0.0501,"OK","FALSE") -> OK | K11: =IF(ABS(H11)<0.0501,"✔","✖") -> ✔
A12: 10 | B12: =B11*1.02 -> 0 | C12: 25000 | D12: =+C12+B12 -> 25000 | F12: =+'General Data'!$C$32-'Operating Costs'!D12 -> 70726.496 | G12: =+F12-'General Data'!$B$35 -> 2726.4957 | H12: =+G12/'General Data'!$B$35 -> 0.040095525 | J12: =IF(ABS(H12)<0.0501,"OK","FALSE") -> OK | K12: =IF(ABS(H12)<0.0501,"✔","✖") -> ✔
A13: 11 | B13: =B12*1.02 -> 0 | C13: 25555 | D13: =+C13+B13 -> 25555 | F13: =+'General Data'!$C$32-'Operating Costs'!D13 -> 70171.496 | G13: =+F13-'General Data'!$B$35 -> 2171.4957 | H13: =+G13/'General Data'!$B$35 -> 0.031933761 | J13: =IF(ABS(H13)<0.0501,"OK","FALSE") -> OK | K13: =IF(ABS(H13)<0.0501,"✔","✖") -> ✔
A14: 12 | B14: =B13*1.02 -> 0 | C14: 24987 | D14: =+C14+B14 -> 24987 | F14: =+'General Data'!$C$32-'Operating Costs'!D14 -> 70739.496 | G14: =+F14-'General Data'!$B$35 -> 2739.4957 | H14: =+G14/'General Data'!$B$35 -> 0.040286702 | J14: =IF(ABS(H14)<0.0501,"OK","FALSE") -> OK | K14: =IF(ABS(H14)<0.0501,"✔","✖") -> ✔
A15: 13 | B15: =B14*1.02 -> 0 | C15: 26987 | D15: =+C15+B15 -> 26987 | F15: =+'General Data'!$C$32-'Operating Costs'!D15 -> 68739.496 | G15: =+F15-'General Data'!$B$35 -> 739.49573 | H15: =+G15/'General Data'!$B$35 -> 0.010874937 | J15: =IF(ABS(H15)<0.0501,"OK","FALSE") -> OK | K15: =IF(ABS(H15)<0.0501,"✔","✖") -> ✔
A16: 14 | B16: =B15*1.02 -> 0 | C16: 25678 | D16: =+C16+B16 -> 25678 | F16: =+'General Data'!$C$32-'Operating Costs'!D16 -> 70048.496 | G16: =+F16-'General Data'!$B$35 -> 2048.4957 | H16: =+G16/'General Data'!$B$35 -> 0.030124937 | J16: =IF(ABS(H16)<0.0501,"OK","FALSE") -> OK | K16: =IF(ABS(H16)<0.0501,"✔","✖") -> ✔
A17: 15 | B17: =B16*1.02 -> 0 | C17: 25900 | D17: =+C17+B17 -> 25900 | F17: =+'General Data'!$C$32-'Operating Costs'!D17 -> 69826.496 | G17: =+F17-'General Data'!$B$35 -> 1826.4957 | H17: =+G17/'General Data'!$B$35 -> 0.026860231 | J17: =IF(ABS(H17)<0.0501,"OK","FALSE") -> OK | K17: =IF(ABS(H17)<0.0501,"✔","✖") -> ✔

Sheet CO2 Impact
A1: PORTFOLIO DEMO | C1: ENERGY SAVINGS REPORT | M1: DEMO-ESCO-01
A3: 0 | B3: Reference System Consumption [kWh] | C3: ='General Data'!B28 -> 1080000 | D3: 0.00053 | E3: CO2 Emissions Before Reconstruction | F3: =C3*D3 -> 572.4 | G3: Savings [%] | H3: Electricity Savings [kWh] | I3: CO2 Reduction [t] | K3: CO2 Before Reconstruction | L3: CO2 After Reconstruction | M3: CO2 Reduction [t] | N3: Savings [%] | O3: =H3 -> Electricity Savings [kWh]
A4: 1 | B4: Consumption in Guarantee Year 1 [kWh] | C4: =+'Year 1'!C16 -> 367300 | D4: 0.00053 | E4: CO2 Emissions in Year 1 | F4: =+C4*D4 -> 194.669 | G4: =+($F$3-F4)/$F$3 -> 0.65990741 | H4: =+$C$3-C4 -> 712700 | I4: =+H4*D4 -> 377.731 | K4: =+$C$3*$D$3 -> 572.4 | L4: =+F4 -> 194.669 | M4: =+I4 -> 377.731 | N4: =+G4 -> 0.65990741 | O4: =+H4 -> 712700
A5: 2 | B5: Consumption in Guarantee Year 2 [kWh] | C5: ='System Consumption'!B4 -> 366198.1 | D5: 0.00053 | E5: CO2 Emissions in Year 2 | F5: =+C5*D5 -> 194.08499 | G5: =+($F$3-F5)/$F$3 -> 0.66092769 | H5: =+$C$3-C5 -> 713801.9 | I5: =+H5*D5 -> 378.31501 | K5: =+$C$3*$D$3 -> 572.4 | L5: =+F5 -> 194.08499 | M5: =+I5 -> 378.31501 | N5: =+G5 -> 0.66092769 | O5: =+H5 -> 713801.9
A6: 3 | B6: Consumption in Guarantee Year 3 [kWh] | C6: ='System Consumption'!B5 -> 365099.51 | D6: 0.00053 | E6: CO2 Emissions in Year 3 | F6: =+C6*D6 -> 193.50274 | G6: =+($F$3-F6)/$F$3 -> 0.6619449 | H6: =+$C$3-C6 -> 714900.49 | I6: =+H6*D6 -> 378.89726 | K6: =+$C$3*$D$3 -> 572.4 | L6: =+F6 -> 193.50274 | M6: =+I6 -> 378.89726 | N6: =+G6 -> 0.6619449 | O6: =+H6 -> 714900.49
A7: 4 | B7: Consumption in Guarantee Year 4 [kWh] | C7: ='System Consumption'!B6 -> 364004.21 | D7: 0.00053 | E7: CO2 Emissions in Year 4 | F7: =+C7*D7 -> 192.92223 | G7: =+($F$3-F7)/$F$3 -> 0.66295907 | H7: =+$C$3-C7 -> 715995.79 | I7: =+H7*D7 -> 379.47777 | K7: =+$C$3*$D$3 -> 572.4 | L7: =+F7 -> 192.92223 | M7: =+I7 -> 379.47777 | N7: =+G7 -> 0.66295907 | O7: =+H7 -> 715995.79
A8: 5 | B8: Consumption in Guarantee Year 5 [kWh] | C8: ='System Consumption'!B7 -> 362912.19 | D8: 0.00053 | E8: CO2 Emissions in Year 5 | F8: =+C8*D8 -> 192.34346 | G8: =+($F$3-F8)/$F$3 -> 0.66397019 | H8: =+$C$3-C8 -> 717087.81 | I8: =+H8*D8 -> 380.05654 | K8: =+$C$3*$D$3 -> 572.4 | L8: =+F8 -> 192.34346 | M8: =+I8 -> 380.05654 | N8: =+G8 -> 0.66397019 | O8: =+H8 -> 717087.81
A9: 6 | B9: Consumption in Guarantee Year 6 [kWh] | C9: ='System Consumption'!B8 -> 361823.46 | D9: 0.00053 | E9: CO2 Emissions in Year 6 | F9: =+C9*D9 -> 191.76643 | G9: =+($F$3-F9)/$F$3 -> 0.66497828 | H9: =+$C$3-C9 -> 718176.54 | I9: =+H9*D9 -> 380.63357 | K9: =+$C$3*$D$3 -> 572.4 | L9: =+F9 -> 191.76643 | M9: =+I9 -> 380.63357 | N9: =+G9 -> 0.66497828 | O9: =+H9 -> 718176.54
A10: 7 | B10: Consumption in Guarantee Year 7 [kWh] | C10: ='System Consumption'!B9 -> 360737.99 | D10: 0.00053 | E10: CO2 Emissions in Year 7 | F10: =+C10*D10 -> 191.19113 | G10: =+($F$3-F10)/$F$3 -> 0.66598334 | H10: =+$C$3-C10 -> 719262.01 | I10: =+H10*D10 -> 381.20887 | K10: =+$C$3*$D$3 -> 572.4 | L10: =+F10 -> 191.19113 | M10: =+I10 -> 381.20887 | N10: =+G10 -> 0.66598334 | O10: =+H10 -> 719262.01
A11: 8 | B11: Consumption in Guarantee Year 8 [kWh] | C11: ='System Consumption'!B10 -> 359655.77 | D11: 0.00053 | E11: CO2 Emissions in Year 8 | F11: =+C11*D11 -> 190.61756 | G11: =+($F$3-F11)/$F$3 -> 0.66698539 | H11: =+$C$3-C11 -> 720344.23 | I11: =+H11*D11 -> 381.78244 | K11: =+$C$3*$D$3 -> 572.4 | L11: =+F11 -> 190.61756 | M11: =+I11 -> 381.78244 | N11: =+G11 -> 0.66698539 | O11: =+H11 -> 720344.23
A12: 9 | B12: Consumption in Guarantee Year 9 [kWh] | C12: ='System Consumption'!B11 -> 358576.81 | D12: 0.00053 | E12: CO2 Emissions in Year 9 | F12: =+C12*D12 -> 190.04571 | G12: =+($F$3-F12)/$F$3 -> 0.66798444 | H12: =+$C$3-C12 -> 721423.19 | I12: =+H12*D12 -> 382.35429 | K12: =+$C$3*$D$3 -> 572.4 | L12: =+F12 -> 190.04571 | M12: =+I12 -> 382.35429 | N12: =+G12 -> 0.66798444 | O12: =+H12 -> 721423.19
A13: 10 | B13: Consumption in Guarantee Year 10 [kWh] | C13: ='System Consumption'!B12 -> 357501.08 | D13: 0.00053 | E13: CO2 Emissions in Year 10 | F13: =+C13*D13 -> 189.47557 | G13: =+($F$3-F13)/$F$3 -> 0.66898049 | H13: =+$C$3-C13 -> 722498.92 | I13: =+H13*D13 -> 382.92443 | K13: =+$C$3*$D$3 -> 572.4 | L13: =+F13 -> 189.47557 | M13: =+I13 -> 382.92443 | N13: =+G13 -> 0.66898049 | O13: =+H13 -> 722498.92
A14: 11 | B14: Consumption in Guarantee Year 11 [kWh] | C14: ='System Consumption'!B13 -> 356428.57 | D14: 0.00053 | E14: CO2 Emissions in Year 11 | F14: =+C14*D14 -> 188.90714 | G14: =+($F$3-F14)/$F$3 -> 0.66997354 | H14: =+$C$3-C14 -> 723571.43 | I14: =+H14*D14 -> 383.49286 | K14: =+$C$3*$D$3 -> 572.4 | L14: =+F14 -> 188.90714 | M14: =+I14 -> 383.49286 | N14: =+G14 -> 0.66997354 | O14: =+H14 -> 723571.43
A15: 12 | B15: Consumption in Guarantee Year 12 [kWh] | C15: ='System Consumption'!B14 -> 355359.29 | D15: 0.00053 | E15: CO2 Emissions in Year 12 | F15: =+C15*D15 -> 188.34042 | G15: =+($F$3-F15)/$F$3 -> 0.67096362 | H15: =+$C$3-C15 -> 724640.71 | I15: =+H15*D15 -> 384.05958 | K15: =+$C$3*$D$3 -> 572.4 | L15: =+F15 -> 188.34042 | M15: =+I15 -> 384.05958 | N15: =+G15 -> 0.67096362 | O15: =+H15 -> 724640.71
A16: 13 | B16: Consumption in Guarantee Year 13 [kWh] | C16: ='System Consumption'!B15 -> 354293.21 | D16: 0.00053 | E16: CO2 Emissions in Year 13 | F16: =+C16*D16 -> 187.7754 | G16: =+($F$3-F16)/$F$3 -> 0.67195073 | H16: =+$C$3-C16 -> 725706.79 | I16: =+H16*D16 -> 384.6246 | K16: =+$C$3*$D$3 -> 572.4 | L16: =+F16 -> 187.7754 | M16: =+I16 -> 384.6246 | N16: =+G16 -> 0.67195073 | O16: =+H16 -> 725706.79
A17: 14 | B17: Consumption in Guarantee Year 14 [kWh] | C17: ='System Consumption'!B16 -> 353230.33 | D17: 0.00053 | E17: CO2 Emissions in Year 14 | F17: =C17*D17 -> 187.21207 | G17: =($F$3-F17)/$F$3 -> 0.67293488 | H17: =$C$3-C17 -> 726769.67 | I17: =H17*D17 -> 385.18793 | K17: =$C$3*$D$3 -> 572.4 | L17: =F17 -> 187.21207 | M17: =I17 -> 385.18793 | N17: =G17 -> 0.67293488 | O17: =H17 -> 726769.67
A18: 15 | B18: Consumption in Guarantee Year 15 [kWh] | C18: ='System Consumption'!B17 -> 352170.64 | D18: 0.00053 | E18: CO2 Emissions in Year 15 | F18: =C18*D18 -> 186.65044 | G18: =($F$3-F18)/$F$3 -> 0.67391608 | H18: =$C$3-C18 -> 727829.36 | I18: =H18*D18 -> 385.74956 | K18: =$C$3*$D$3 -> 572.4 | L18: =F18 -> 186.65044 | M18: =I18 -> 385.74956 | N18: =G18 -> 0.67391608 | O18: =H18 -> 727829.36
A19: 15-Year Total | K19: =SUM(K4:K18) -> 8586 | L19: =SUM(L4:L18) -> 2859.5043 | M19: =K19-L19 -> 5726.4957 | N19: =M19/K19 -> 0.66695734 | O19: =SUM(O4:O18) -> 10804709

Sheet Cost Comparison
A1: PORTFOLIO DEMO | C1: ENERGY SAVINGS REPORT | I1: DEMO-ESCO-01
B3: Guarantee Year 1 | C3: Without Reconstruction | D3: After Reconstruction
B4: Electricity | C4: =+'Energy Price'!C7 -> 79344.923 | D4: =+'Energy Price'!F7 -> 26984.621
B5: Maintenance | C5: =+'General Data'!C31 -> 22222.222
B6: Service Fee | D6: =+'General Data'!B47 -> 18000
B7: TOTAL | C7: =SUM(C4:C6) -> 101567.15 | D7: =SUM(D4:D6) -> 44984.621
B8: SAVINGS | D8: =+C7-D7 -> 56582.525

Sheet Energy Price
A1: PORTFOLIO DEMO | C1: ENERGY SAVINGS REPORT | M1: DEMO-ESCO-01
A3: Reference System Consumption [kWh] | B3: =+'General Data'!B28 -> 1080000
A4: Reference Electricity Price | B4: =+'General Data'!B33 -> 8.2
A5: Exchange Rate | B5: =+'General Data'!B37 -> 117
A6: Guarantee Year | B6: Before Reconstruction | C6: Without Reconstruction | D6: Increase | E6: % | F6: After Reconstruction | G6: Electricity Savings [%] | H6: Electricity Price | I6: Price Increase
A7: 1. year | B7: =+'General Data'!C30 -> 73504.274 | C7: =+$B$3*H7/$B$5 -> 79344.923 | D7: =+C7-B7 -> 5840.6496 | E7: =(C7-B7)/B7 -> 0.07946 | F7: ='System Consumption'!B3*H7/$B$5 -> 26984.621 | G7: =+(B7-F7)/B7 -> 0.63288365 | H7: =+(5.08+2.808+0.093+0.015)*1.075 -> 8.5957 | I7: =+(H7-B4)/B4 -> 0.048256098
A8: 2. year | B8: =+B7 -> 73504.274 | C8: =+$B$3*H8/$B$5 -> 81328.546 | D8: =+C8-B8 -> 7824.2726 | E8: =(C8-B8)/B8 -> 0.1064465 | F8: ='System Consumption'!B4*H8/$B$5 -> 27576.258 | G8: =+(B8-F8)/B8 -> 0.62483462 | H8: =H7*1.025 -> 8.8105925 | I8: =(H8-$B$4)/$B$4 -> 0.0744625
A9: 3. year | B9: =+B8 -> 73504.274 | C9: =+$B$3*H9/$B$5 -> 83361.76 | D9: =+C9-B9 -> 9857.4863 | E9: =(C9-B9)/B9 -> 0.13410766 | F9: ='System Consumption'!B5*H9/$B$5 -> 28180.868 | G9: =+(B9-F9)/B9 -> 0.61660912 | H9: =H8*1.025 -> 9.0308573 | I9: =(H9-$B$4)/$B$4 -> 0.10132406
A10: 4. year | B10: =+B9 -> 73504.274 | C10: =+$B$3*H10/$B$5 -> 85445.804 | D10: =+C10-B10 -> 11941.53 | E10: =(C10-B10)/B10 -> 0.16246035 | F10: ='System Consumption'!B6*H10/$B$5 -> 28798.733 | G10: =+(B10-F10)/B10 -> 0.60820328 | H10: =H9*1.025 -> 9.2566287 | I10: =(H10-$B$4)/$B$4 -> 0.12885716
A11: 5. year | B11: =+B10 -> 73504.274 | C11: =+$B$3*H11/$B$5 -> 87581.949 | D11: =+C11-B11 -> 14077.675 | E11: =(C11-B11)/B11 -> 0.19152186 | F11: ='System Consumption'!B7*H11/$B$5 -> 29430.146 | G11: =+(B11-F11)/B11 -> 0.59961314 | H11: =H10*1.025 -> 9.4880445 | I11: =(H11-$B$4)/$B$4 -> 0.15707859
A12: 6. year | B12: =+B11 -> 73504.274 | C12: =+$B$3*H12/$B$5 -> 89771.498 | D12: =+C12-B12 -> 16267.224 | E12: =(C12-B12)/B12 -> 0.22130991 | F12: ='System Consumption'!B8*H12/$B$5 -> 30075.402 | G12: =+(B12-F12)/B12 -> 0.59083465 | H12: =H11*1.025 -> 9.7252456 | I12: =(H12-$B$4)/$B$4 -> 0.18600556
A13: 7. year | B13: =+B12 -> 73504.274 | C13: =+$B$3*H13/$B$5 -> 92015.785 | D13: =+C13-B13 -> 18511.512 | E13: =(C13-B13)/B13 -> 0.25184266 | F13: ='System Consumption'!B9*H13/$B$5 -> 30734.805 | G13: =+(B13-F13)/B13 -> 0.5818637 | H13: =H12*1.025 -> 9.9683767 | I13: =(H13-$B$4)/$B$4 -> 0.2156557
A14: 8. year | B14: =+B13 -> 73504.274 | C14: =+$B$3*H14/$B$5 -> 94316.18 | D14: =+C14-B14 -> 20811.906 | E14: =(C14-B14)/B14 -> 0.28313872 | F14: ='System Consumption'!B10*H14/$B$5 -> 31408.665 | G14: =+(B14-F14)/B14 -> 0.57269606 | H14: =H13*1.025 -> 10.217586 | I14: =(H14-$B$4)/$B$4 -> 0.24604709
A15: 9. year | B15: =+B14 -> 73504.274 | C15: =+$B$3*H15/$B$5 -> 96674.084 | D15: =+C15-B15 -> 23169.811 | E15: =(C15-B15)/B15 -> 0.31521719 | F15: ='System Consumption'!B11*H15/$B$5 -> 32097.3 | G15: =+(B15-F15)/B15 -> 0.56332743 | H15: =H14*1.025 -> 10.473026 | I15: =(H15-$B$4)/$B$4 -> 0.27719827
A16: 10. year | B16: =+B15 -> 73504.274 | C16: =+$B$3*H16/$B$5 -> 99090.936 | D16: =+C16-B16 -> 25586.663 | E16: =(C16-B16)/B16 -> 0.34809762 | F16: ='System Consumption'!B12*H16/$B$5 -> 32801.034 | G16: =+(B16-F16)/B16 -> 0.55375338 | H16: =H15*1.025 -> 10.734851 | I16: =(H16-$B$4)/$B$4 -> 0.30912822
A17: 11. year | B17: =+B16 -> 73504.274 | C17: =+$B$3*H17/$B$5 -> 101568.21 | D17: =+C17-B17 -> 28063.936 | E17: =(C17-B17)/B17 -> 0.38180006 | F17: ='System Consumption'!B13*H17/$B$5 -> 33520.196 | G17: =+(B17-F17)/B17 -> 0.54396942 | H17: =H16*1.025 -> 11.003223 | I17: =(H17-$B$4)/$B$4 -> 0.34185643
A18: 12. year | B18: =+B17 -> 73504.274 | C18: =+$B$3*H18/$B$5 -> 104107.41 | D18: =+C18-B18 -> 30603.141 | E18: =(C18-B18)/B18 -> 0.41634506 | F18: ='System Consumption'!B14*H18/$B$5 -> 34255.127 | G18: =+(B18-F18)/B18 -> 0.53397095 | H18: =H17*1.025 -> 11.278303 | I18: =(H18-$B$4)/$B$4 -> 0.37540284
A19: 13. year | B19: =+B18 -> 73504.274 | C19: =+$B$3*H19/$B$5 -> 106710.1 | D19: =+C19-B19 -> 33205.827 | E19: =(C19-B19)/B19 -> 0.45175369 | F19: ='System Consumption'!B15*H19/$B$5 -> 35006.17 | G19: =+(B19-F19)/B19 -> 0.52375327 | H19: =H18*1.025 -> 11.560261 | I19: =(H19-$B$4)/$B$4 -> 0.40978791
... A21: 15. year | B21: =+B20 -> 73504.274 | C21: =+$B$3*H21/$B$5 -> 112112.3 | D21: =+C21-B21 -> 38608.026 | E21: =(C21-B21)/B21 -> 0.52524872 | F21: ='System Consumption'!B17*H21/$B$5 -> 36558.018 | G21: =+(B21-F21)/B21 -> 0.50264091 | H21: =H20*1.025 -> 12.145499 | I21: =(H21-$B$4)/$B$4 -> 0.48115842

Sheet Average Price
A1: PORTFOLIO DEMO | C1: ENERGY SAVINGS REPORT | I1: DEMO-ESCO-01
A2: Guarantee Year 1
A3: Year | B3: Month | C3: Energy Price | D3: Distribution Charge | E3: System Fee | F3: Efficiency Fee | G3: Excise Factor | H3: Net Price
A4: 1 | B4: January | C4: 5.08 | D4: 2.808 | E4: 0.093 | F4: 0.015 | G4: 1.075 | H4: =+(C4+D4+E4+F4)*G4 -> 8.5957
A5: 1 | B5: February | C5: 5.08 | D5: 2.808 | E5: 0.093 | F5: 0.015 | G5: 1.075 | H5: =+(C5+D5+E5+F5)*G5 -> 8.5957
A6: 1 | B6: March | C6: 5.08 | D6: 2.808 | E6: 0.093 | F6: 0.015 | G6: 1.075 | H6: =+(C6+D6+E6+F6)*G6 -> 8.5957
A7: 1 | B7: April | C7: 5.08 | D7: 2.808 | E7: 0.093 | F7: 0.015 | G7: 1.075 | H7: =+(C7+D7+E7+F7)*G7 -> 8.5957
A8: 1 | B8: May | C8: 5.08 | D8: 2.808 | E8: 0.093 | F8: 0.015 | G8: 1.075 | H8: =+(C8+D8+E8+F8)*G8 -> 8.5957
A9: 1 | B9: June | C9: 5.08 | D9: 2.808 | E9: 0.437 | F9: 0.015 | G9: 1.075 | H9: =+(C9+D9+E9+F9)*G9 -> 8.9655
A10: 1 | B10: July | C10: 5.35 | D10: 3.221 | E10: 0.437 | F10: 0.015 | G10: 1.075 | H10: =+(C10+D10+E10+F10)*G10 -> 9.699725
A11: 1 | B11: August | C11: 5.35 | D11: 3.221 | E11: 0.437 | F11: 0.015 | G11: 1.075 | H11: =+(C11+D11+E11+F11)*G11 -> 9.699725
A12: 1 | B12: September | C12: 5.35 | D12: 3.221 | E12: 0.437 | F12: 0.015 | G12: 1.075 | H12: =+(C12+D12+E12+F12)*G12 -> 9.699725
A13: 1 | B13: October | C13: 5.35 | D13: 3.221 | E13: 0.437 | F13: 0.015 | G13: 1.075 | H13: =+(C13+D13+E13+F13)*G13 -> 9.699725
A14: 1 | B14: November | C14: 5.35 | D14: 3.221 | E14: 0.437 | F14: 0.015 | G14: 1.075 | H14: =+(C14+D14+E14+F14)*G14 -> 9.699725
A15: 1 | B15: December | C15: 5.35 | D15: 3.221 | E15: 0.437 | F15: 0.015 | G15: 1.075 | H15: =+(C15+D15+E15+F15)*G15 -> 9.699725
H16: =AVERAGE(H4:H15) -> 9.1785292

Sheet System Consumption
A1: PORTFOLIO DEMO | B1: ENERGY SAVINGS REPORT | K1: DEMO-ESCO-01
A2: Guarantee Year | B2: Total System Electricity Consumption [kWh] | C2: Consumption excl. Additional Loads [kWh]
A3: 1 | B3: ='Year 1'!C16 -> 367300 | C3: ='Year 1'!F16 -> 348227
A4: 2 | B4: =B3*0.997 -> 366198.1 | C4: =C3*0.997 -> 347182.32
A5: 3 | B5: =B4*0.997 -> 365099.51 | C5: =C4*0.997 -> 346140.77
A6: 4 | B6: =B5*0.997 -> 364004.21 | C6: =C5*0.997 -> 345102.35
A7: 5 | B7: =B6*0.997 -> 362912.19 | C7: =C6*0.997 -> 344067.04
A8: 6 | B8: =B7*0.997 -> 361823.46 | C8: =C7*0.997 -> 343034.84
A9: 7 | B9: =B8*0.997 -> 360737.99 | C9: =C8*0.997 -> 342005.74
A10: 8 | B10: =B9*0.997 -> 359655.77 | C10: =C9*0.997 -> 340979.72
A11: 9 | B11: =B10*0.997 -> 358576.81 | C11: =C10*0.997 -> 339956.78
A12: 10 | B12: =B11*0.997 -> 357501.08 | C12: =C11*0.997 -> 338936.91
A13: 11 | B13: =B12*0.997 -> 356428.57 | C13: =C12*0.997 -> 337920.1
A14: 12 | B14: =B13*0.997 -> 355359.29 | C14: =C13*0.997 -> 336906.34
A15: 13 | B15: =B14*0.997 -> 354293.21 | C15: =C14*0.997 -> 335895.62
... A17: 15 | B17: =B16*0.997 -> 352170.64 | C17: =C16*0.997 -> 333883.27
